<robot
  name="iiwa_7_filter">
  <link
    name="base_link">
    <inertial>
      <origin
        xyz="-5.3623E-18 -1.2682E-34 0.074406"
        rpy="0 0 0" />
      <mass
        value="4.6242" />
      <inertia
        ixx="0.0212"
        ixy="-2.9968E-35"
        ixz="-1.6116E-20"
        iyy="0.0212"
        iyz="-7.0674E-35"
        izz="0.020954" />
    </inertial>
    <visual>
      <origin
        xyz="0 0 0"
        rpy="0 0 0" />
      <geometry>
        <mesh
          filename="package://iiwa_7_filter/meshes/base_link.STL" />
      </geometry>
      <material
        name="">
        <color
          rgba="0.75294 0.75294 0.75294 1" />
      </material>
    </visual>
    <collision>
      <origin
        xyz="0 0 0"
        rpy="0 0 0" />
      <geometry>
        <mesh
          filename="package://iiwa_7_filter/meshes/base_link.STL" />
      </geometry>
    </collision>
  </link>
  <link
    name="cell_1">
    <inertial>
      <origin
        xyz="6.5052E-08 -0.027362 0.075175"
        rpy="0 0 0" />
      <mass
        value="2.6569" />
      <inertia
        ixx="0.0094044"
        ixy="3.9594E-10"
        ixz="7.419E-20"
        iyy="0.0087413"
        iyz="0.0018217"
        izz="0.0081356" />
    </inertial>
    <visual>
      <origin
        xyz="0 0 0"
        rpy="0 0 0" />
      <geometry>
        <mesh
          filename="package://iiwa_7_filter/meshes/cell_1.STL" />
      </geometry>
      <material
        name="">
        <color
          rgba="0.75294 0.75294 0.75294 1" />
      </material>
    </visual>
    <collision>
      <origin
        xyz="0 0 0"
        rpy="0 0 0" />
      <geometry>
        <mesh
          filename="package://iiwa_7_filter/meshes/cell_1.STL" />
      </geometry>
    </collision>
  </link>
  <joint
    name="joint_1"
    type="revolute">
    <origin
      xyz="0 0 0.17"
      rpy="0 0 0" />
    <parent
      link="base_link" />
    <child
      link="cell_1" />
    <axis
      xyz="0 0 1" />
    <limit
      lower="-3.14"
      upper="3.14"
      effort="0"
      velocity="5.236" />
    <safety_controller
      k_position="100"
      k_velocity="100" />
  </joint>
  <link
    name="cell_2">
    <inertial>
      <origin
        xyz="7.4424E-08 -0.039428 0.011073"
        rpy="0 0 0" />
      <mass
        value="5.8041" />
      <inertia
        ixx="0.037363"
        ixy="7.8671E-09"
        ixz="-1.4709E-08"
        iyy="0.024656"
        iyz="0.0019112"
        izz="0.027578" />
    </inertial>
    <visual>
      <origin
        xyz="0 0 0"
        rpy="0 0 0" />
      <geometry>
        <mesh
          filename="package://iiwa_7_filter/meshes/cell_2.STL" />
      </geometry>
      <material
        name="">
        <color
          rgba="0.75294 0.75294 0.75294 1" />
      </material>
    </visual>
    <collision>
      <origin
        xyz="0 0 0"
        rpy="0 0 0" />
      <geometry>
        <mesh
          filename="package://iiwa_7_filter/meshes/cell_2.STL" />
      </geometry>
    </collision>
  </link>
  <joint
    name="joint_2"
    type="revolute">
    <origin
      xyz="0 0 0.17"
      rpy="-1.5708 0 0" />
    <parent
      link="cell_1" />
    <child
      link="cell_2" />
    <axis
      xyz="0 0 -1" />
    <limit
      lower="-2.094"
      upper="2.094"
      effort="0"
      velocity="5.236" />
    <safety_controller
      k_position="100"
      k_velocity="100" />
  </joint>
  <link
    name="cell_3">
    <inertial>
      <origin
        xyz="-1.2843E-07 0.01659 0.07"
        rpy="0 0 0" />
      <mass
        value="3.7994" />
      <inertia
        ixx="0.021074"
        ixy="-1.2707E-08"
        ixz="3.6634E-08"
        iyy="0.019978"
        iyz="-0.0038344"
        izz="0.011781" />
    </inertial>
    <visual>
      <origin
        xyz="0 0 0"
        rpy="0 0 0" />
      <geometry>
        <mesh
          filename="package://iiwa_7_filter/meshes/cell_3.STL" />
      </geometry>
      <material
        name="">
        <color
          rgba="0.75294 0.75294 0.75294 1" />
      </material>
    </visual>
    <collision>
      <origin
        xyz="0 0 0"
        rpy="0 0 0" />
      <geometry>
        <mesh
          filename="package://iiwa_7_filter/meshes/cell_3.STL" />
      </geometry>
    </collision>
  </link>
  <joint
    name="joint_3"
    type="revolute">
    <origin
      xyz="0 -0.2 0"
      rpy="1.5708 0 0" />
    <parent
      link="cell_2" />
    <child
      link="cell_3" />
    <axis
      xyz="0 0 1" />
    <limit
      lower="-3.14"
      upper="3.14"
      effort="0"
      velocity="5.236" />
    <safety_controller
      k_position="100"
      k_velocity="100" />
  </joint>
  <link
    name="cell_4">
    <inertial>
      <origin
        xyz="-7.4977E-08 0.040494 0.011144"
        rpy="0 0 0" />
      <mass
        value="5.8041" />
      <inertia
        ixx="0.038048"
        ixy="8.5235E-09"
        ixz="1.6335E-08"
        iyy="0.024676"
        iyz="-0.0020163"
        izz="0.028244" />
    </inertial>
    <visual>
      <origin
        xyz="0 0 0"
        rpy="0 0 0" />
      <geometry>
        <mesh
          filename="package://iiwa_7_filter/meshes/cell_4.STL" />
      </geometry>
      <material
        name="">
        <color
          rgba="0.75294 0.75294 0.75294 1" />
      </material>
    </visual>
    <collision>
      <origin
        xyz="0 0 0"
        rpy="0 0 0" />
      <geometry>
        <mesh
          filename="package://iiwa_7_filter/meshes/cell_4.STL" />
      </geometry>
    </collision>
  </link>
  <joint
    name="joint_4"
    type="revolute">
    <origin
      xyz="0 0 0.2"
      rpy="1.5708 0 0" />
    <parent
      link="cell_3" />
    <child
      link="cell_4" />
    <axis
      xyz="0 0 1" />
    <limit
      lower="-2.093"
      upper="2.093"
      effort="0"
      velocity="5.236" />
    <safety_controller
      k_position="100"
      k_velocity="100" />
  </joint>
  <link
    name="cell_5">
    <inertial>
      <origin
        xyz="1.3229E-07 -0.017429 0.07"
        rpy="0 0 0" />
      <mass
        value="3.711" />
      <inertia
        ixx="0.019984"
        ixy="-1.2722E-08"
        ixz="-3.5518E-08"
        iyy="0.018857"
        iyz="0.003773"
        izz="0.011564" />
    </inertial>
    <visual>
      <origin
        xyz="0 0 0"
        rpy="0 0 0" />
      <geometry>
        <mesh
          filename="package://iiwa_7_filter/meshes/cell_5.STL" />
      </geometry>
      <material
        name="">
        <color
          rgba="0.75294 0.75294 0.75294 1" />
      </material>
    </visual>
    <collision>
      <origin
        xyz="0 0 0"
        rpy="0 0 0" />
      <geometry>
        <mesh
          filename="package://iiwa_7_filter/meshes/cell_5.STL" />
      </geometry>
    </collision>
  </link>
  <joint
    name="joint_5"
    type="revolute">
    <origin
      xyz="0 0.2 0"
      rpy="-1.5708 0 0" />
    <parent
      link="cell_4" />
    <child
      link="cell_5" />
    <axis
      xyz="0 0 1" />
    <limit
      lower="-3.14"
      upper="3.14"
      effort="0"
      velocity="5.236" />
    <safety_controller
      k_position="100"
      k_velocity="100" />
  </joint>
  <link
    name="cell_6">
    <inertial>
      <origin
        xyz="2.2309E-18 0.02 -0.02"
        rpy="0 0 0" />
      <mass
        value="3.645" />
      <inertia
        ixx="0.016676"
        ixy="-3.3572E-35"
        ixz="-1.301E-18"
        iyy="0.015377"
        iyz="4.0312E-36"
        izz="0.01237" />
    </inertial>
    <visual>
      <origin
        xyz="0 0 0"
        rpy="0 0 0" />
      <geometry>
        <mesh
          filename="package://iiwa_7_filter/meshes/cell_6.STL" />
      </geometry>
      <material
        name="">
        <color
          rgba="0.82353 0.82353 0.82353 1" />
      </material>
    </visual>
    <collision>
      <origin
        xyz="0 0 0"
        rpy="0 0 0" />
      <geometry>
        <mesh
          filename="package://iiwa_7_filter/meshes/cell_6.STL" />
      </geometry>
    </collision>
  </link>
  <joint
    name="joint_6"
    type="revolute">
    <origin
      xyz="0 0 0.2"
      rpy="-1.5708 0 0" />
    <parent
      link="cell_5" />
    <child
      link="cell_6" />
    <axis
      xyz="0 0 1" />
    <limit
      lower="-2.093"
      upper="2.093"
      effort="0"
      velocity="5.236" />
    <safety_controller
      k_position="100"
      k_velocity="100" />
  </joint>
  <link
    name="cell_7">
    <inertial>
      <origin
        xyz="1.2272E-18 0 0.03"
        rpy="0 0 0" />
      <mass
        value="0.67858" />
      <inertia
        ixx="0.0008143"
        ixy="0"
        ixz="-2.351E-36"
        iyy="0.0008143"
        iyz="-2.3604E-36"
        izz="0.0012215" />
    </inertial>
    <visual>
      <origin
        xyz="0 0 0"
        rpy="0 0 0" />
      <geometry>
        <mesh
          filename="package://iiwa_7_filter/meshes/cell_7.STL" />
      </geometry>
      <material
        name="">
        <color
          rgba="0.75294 0.75294 0.75294 1" />
      </material>
    </visual>
    <collision>
      <origin
        xyz="0 0 0"
        rpy="0 0 0" />
      <geometry>
        <mesh
          filename="package://iiwa_7_filter/meshes/cell_7.STL" />
      </geometry>
    </collision>
  </link>
  <joint
    name="joint_7"
    type="revolute">
    <origin
      xyz="0 -0.055 0"
      rpy="1.5708 0 0" />
    <parent
      link="cell_6" />
    <child
      link="cell_7" />
    <axis
      xyz="0 0 1" />
    <limit
      lower="-3.14"
      upper="3.14"
      effort="0"
      velocity="5.236" />
    <safety_controller
      k_position="100"
      k_velocity="100" />
  </joint>
</robot>